Workbook

Sheet Source Data
A1: WOOLWORTHS GROUP (ASX: WOW) — HISTORICAL DATA | AUD Millions
A2: All figures verified from Woolworths Annual Reports FY2022–FY2025.
A4: Line Item | B4: Unit | C4: FY2022 | D4: FY2023 | E4: FY2024 | F4: FY2025 | G4: Source
A5: INCOME STATEMENT
A6: Revenue | B6: $m | C6: 60849 | D6: 64294 | E6: 67922 | F6: 69077 | G6: Annual Report
A7: Cost of Sales | B7: $m | C7: 44878 | D7: 47118 | E7: 49370 | F7: 50262 | G7: FY2022 restated — see FY2023 report Note 1.1.1
A8: Gross Profit | B8: $m | C8: =C6-C7 -> 15971 | D8: =D6-D7 -> 17176 | E8: =E6-E7 -> 18552 | F8: =F6-F7 -> 18815 | G8: Calculated: Revenue – COGS
A9: Branch Expenses | B9: $m | C9: 10388 | D9: 10770 | E9: 11707 | F9: 12768 | G9: FY2024 incl $13m NZ impairment. FY2025 incl $346m BIG W + other
A10: Administration Expenses | B10: $m | C10: 3189 | D10: 3684 | E10: 5539 | F10: 4135 | G10: FY2024 incl $1,492m NZ goodwill + $209m Endeavour
A11: Total CODB (reported) | B11: $m | C11: 13577 | D11: 14454 | E11: 17246 | F11: 16903 | G11: Branch + Admin as reported — includes one-off items
A12: One-off / Impairment Items | B12: $m | C12: 0 | D12: 0 | E12: 1701 | F12: 569 | G12: FY24: NZ goodwill $1,492m + Endeavour $209m. FY25: BIG W $346m + other $223m
A13: Underlying CODB | B13: $m | C13: 13577 | D13: 14454 | E13: 15545 | F13: 16334 | G13: CODB excl one-off items — use for trend analysis
A14: EBIT (reported) | B14: $m | C14: 2691 | D14: 2999 | E14: 1616 | F14: 2185 | G14: Gross Profit – Total CODB reported
A15: Underlying EBIT | B15: $m | C15: 2691 | D15: 2999 | E15: 3317 | F15: 2754 | G15: EBIT + one-off items back — key trend metric
A16: Net Finance Costs | B16: $m | C16: 600 | D16: 677 | E16: 740 | F16: 811 | G16: Rising — higher debt post acquisitions
A17: Profit Before Tax | B17: $m | C17: =C14-C16 -> 2091 | D17: =D14-D16 -> 2322 | E17: =E14-E16 -> 876 | F17: =F14-F16 -> 1374 | G17: Calculated: EBIT – Net Finance Costs
A18: Income Tax Expense | B18: $m | C18: 534 | D18: 693 | E18: 759 | F18: 421 | G18: FY2024 rate distorted by non-deductible impairment
A19: NPAT (reported) | B19: $m | C19: 1547 | D19: 1618 | E19: 108 | F19: 963 | G19: Attributable to equity holders
A20: Underlying NPAT | B20: $m | C20: 1547 | D20: 1618 | E20: 1399 | F20: 963 | G20: FY2024: adds back ~$1,291m after-tax impairment impact
A22: MARGIN ANALYSIS
A23: Gross Margin % | B23: % | C23: =(C8/C6) -> 0.26246939 | D23: =(D8/D6) -> 0.26714779 | E23: =(E8/E6) -> 0.27313683 | F23: =(F8/F6) -> 0.2723772 | G23: Calculated
A24: Underlying CODB % | B24: % | C24: =C13/C6 -> 0.2231261 | D24: =D13/D6 -> 0.22481102 | E24: =E13/E6 -> 0.22886546 | F24: =F13/F6 -> 0.23646076 | G24: Underlying CODB / Revenue
A25: EBIT Margin % (reported) | B25: % | C25: =C14/C6 -> 0.044224227 | D25: =D14/D6 -> 0.046645099 | E25: =E14/E6 -> 0.023791997 | F25: =F14/F6 -> 0.031631368 | G25: Calculated
A26: Underlying EBIT Margin % | B26: % | C26: =C15/C6 -> 0.044224227 | D26: =D15/D6 -> 0.046645099 | E26: =E15/E6 -> 0.048835429 | F26: =F15/F6 -> 0.039868552 | G26: Underlying EBIT / Revenue
A27: Net Margin % (reported) | B27: % | C27: =C19/C6 -> 0.02542359 | D27: =D19/D6 -> 0.025165645 | E27: =E19/E6 -> 0.0015900592 | F27: =F19/F6 -> 0.013940964 | G27: Calculated
A29: BALANCE SHEET
A30: Total Current Assets | B30: $m | C30: 6110 | D30: 6375 | E30: 6991 | F30: 6991 | G30: Annual Report
A31: Total Non-Current Assets | B31: $m | C31: 27163 | D31: 27273 | E31: 26945 | F31: 26838 | G31: Annual Report
A32: Total Assets | B32: $m | C32: =SUM(C30:C31) -> 33273 | D32: =SUM(D30:D31) -> 33648 | E32: =SUM(E30:E31) -> 33936 | F32: =SUM(F30:F31) -> 33829 | G32: Calculated
A33: Total Current Liabilities | B33: $m | C33: 10750 | D33: 11886 | E33: 12819 | F33: 12297 | G33: Annual Report
A34: Total Non-Current Liabilities | B34: $m | C34: 16419 | D34: 15197 | E34: 15547 | F34: 16570 | G34: Annual Report
A35: Total Liabilities | B35: $m | C35: =SUM(C33:C34) -> 27169 | D35: =SUM(D33:D34) -> 27083 | E35: =SUM(E33:E34) -> 28366 | F35: =SUM(F33:F34) -> 28867 | G35: Calculated
A36: Total Equity | B36: $m | C36: 6104 | D36: 6565 | E36: 5570 | F36: 4962 | G36: Annual Report
A38: CASH FLOW STATEMENT
A39: Operating Cash Flow | B39: $m | C39: 3378 | D39: 4754 | E39: 4359 | F39: 4550 | G39: Annual Report
A40: Investing Cash Flow | B40: $m | C40: -2457 | D40: -1844 | E40: -2277 | F40: -1926 | G40: Annual Report
A41: Financing Cash Flow | B41: $m | C41: -1337 | D41: -2809 | E41: -1919 | F41: -2649 | G41: Annual Report
A42: Net Change in Cash | B42: $m | C42: =SUM(C39:C41) -> -416 | D42: =SUM(D39:D41) -> 101 | E42: =SUM(E39:E41) -> 163 | F42: =SUM(F39:F41) -> -25 | G42: Calculated
A43: Free Cash Flow | B43: $m | C43: =C39+C40 -> 921 | D43: =D39+D40 -> 2910 | E43: =E39+E40 -> 2082 | F43: =F39+F40 -> 2624 | G43: Calculate: OCF + Investing CF
A46: KEY NOTES FOR YOUR ANALYSIS
...

Sheet Assumptions
A1: Line Items | B1: FY2026E Value | C1: Basis / Rationale (based on FY2022–FY2025 trend) | D1: Low Case | E1: High Case
A2: REVENUE
A3: Revenue Growth % | B3: =('P&L Model'!E2/'P&L Model'!B2)^(1/3)-1 -> 0.043181815 | C3: 3-year CAGR FY2022–FY2025 | D3: =B3-1.5% -> 0.028181815 | E3: =B3+1.5% -> 0.058181815
A4: GROSS MARGIN
A5: Gross Margin % | B5: =AVERAGE('P&L Model'!B6:E6) -> 0.2687828 | C5: Avg FY2022-FY2025 | D5: =B5-0.33% -> 0.2654828 | E5: =B5+0.33% -> 0.2720828
A6: OPERATING COSTS
A7: Underlying CODB % | B7: =AVERAGE('P&L Model'!B11:E11) -> 0.22831584 | C7: Avg FY2022-FY2025 | D7: =B7-0.44% -> 0.22391584 | E7: =B7+0.44% -> 0.23271584
A8: BELOW THE LINE
A9: Net Finance Costs ($m) | B9: 880 | C9: FY2025 Value + Avg movement of FY2022-FY2025 | D9: =B9-10 -> 870 | E9: =B9+10 -> 890
A10: Effective Tax Rate % | B10: 0.29 | C10: FY2024 distorted by non-deductible goodwill write-off | D10: =B10-1% -> 0.28 | E10: =B10+1% -> 0.3
A11: BALANCE SHEET GROWTH
A12: Current Assets Growth % | B12: 0.045 | C12: 3-year CAGR FY2022–FY2025 | D12: =B12-1% -> 0.035 | E12: =B12+1% -> 0.055
A13: Non-Current Assets Growth % | B13: 0.005 | C13: 3-year CAGR FY2022–FY2025 | D13: =B13-0.25% -> 0.0025 | E13: =B13+0.25% -> 0.0075
A14: Current Liabilities Growth % | B14: 0.045 | C14: 3-year CAGR FY2022–FY2025 | D14: =B14-1% -> 0.035 | E14: =B14+1% -> 0.055
A15: Non-Current Liabilities Growth % | B15: 0.003 | C15: 3-year CAGR FY2022–FY2025 | D15: =B15-0.25% -> 0.0005 | E15: =B15+0.25% -> 0.0055
A16: CASH FLOW
A17: OCF / Underlying EBIT ratio | B17: 1.45 | C17: FY2022-FY2025 avg OCF/Underlying EBIT ~1.45x. Strong cash conversion. | D17: 1.25 | E17: 1.65
A18: Capex ($m) | B18: -2100 | C18: FY2025 capex: $2,528m. Slightly higher in FY2026E — ongoing investment cycle. | D18: -2500 | E18: -1800

Sheet P&L Model
A1: Line Item | B1: FY2022 | C1: FY2023 | D1: FY2024 | E1: FY2025 | F1: FY2026E | G1: Notes
A2: Revenue | B2: ='Source Data'!C6 -> 60849 | C2: ='Source Data'!D6 -> 64294 | D2: ='Source Data'!E6 -> 67922 | E2: ='Source Data'!F6 -> 69077 | F2: =E2*(1+Assumptions!B3) -> 72059.87
A3: Cost of Sales (COGS) | B3: ='Source Data'!C7 -> 44878 | C3: ='Source Data'!D7 -> 47118 | D3: ='Source Data'!E7 -> 49370 | E3: ='Source Data'!F7 -> 50262 | F3: =F2*(1-Assumptions!B5) -> 52691.416
A5: GROSS PROFIT | B5: ='Source Data'!C8 -> 15971 | C5: ='Source Data'!D8 -> 17176 | D5: ='Source Data'!E8 -> 18552 | E5: ='Source Data'!F8 -> 18815 | F5: =F2-F3 -> 19368.454
A6: Gross Margin % | B6: ='Source Data'!C23 -> 0.26246939 | C6: ='Source Data'!D23 -> 0.26714779 | D6: ='Source Data'!E23 -> 0.27313683 | E6: ='Source Data'!F23 -> 0.2723772 | F6: =F5/F2 -> 0.2687828
A8: Cost of Doing Business (CODB) | B8: ='Source Data'!C11 -> 13577 | C8: ='Source Data'!D11 -> 14454 | D8: ='Source Data'!E11 -> 17246 | E8: ='Source Data'!F11 -> 16903 | F8: =F10 -> 16452.41
A9: — One-off Items | B9: ='Source Data'!C12 -> 0 | C9: ='Source Data'!D12 -> 0 | D9: ='Source Data'!E12 -> 1701 | E9: ='Source Data'!F12 -> 569 | F9: 0
A10: — Underlying CODB | B10: ='Source Data'!C13 -> 13577 | C10: ='Source Data'!D13 -> 14454 | D10: ='Source Data'!E13 -> 15545 | E10: ='Source Data'!F13 -> 16334 | F10: =F2*Assumptions!B7 -> 16452.41
A11: Underlying CODB % | B11: ='Source Data'!C24 -> 0.2231261 | C11: ='Source Data'!D24 -> 0.22481102 | D11: ='Source Data'!E24 -> 0.22886546 | E11: ='Source Data'!F24 -> 0.23646076 | F11: =F10/F2 -> 0.22831584
A13: EBIT (Reported) | B13: ='Source Data'!C14 -> 2691 | C13: ='Source Data'!D14 -> 2999 | D13: ='Source Data'!E14 -> 1616 | E13: ='Source Data'!F14 -> 2185 | F13: =F5-F10 -> 2916.0444
A14: — Underlying EBIT | B14: ='Source Data'!C15 -> 2691 | C14: ='Source Data'!D15 -> 2999 | D14: ='Source Data'!E15 -> 3317 | E14: ='Source Data'!F15 -> 2754 | F14: =F13 -> 2916.0444
A15: EBIT Margin % (Reported) | B15: ='Source Data'!C25 -> 0.044224227 | C15: ='Source Data'!D25 -> 0.046645099 | D15: ='Source Data'!E25 -> 0.023791997 | E15: ='Source Data'!F25 -> 0.031631368 | F15: =F13/F2 -> 0.040466967
A16: Underlying EBIT Margin % | B16: ='Source Data'!C26 -> 0.044224227 | C16: ='Source Data'!D26 -> 0.046645099 | D16: ='Source Data'!E26 -> 0.048835429 | E16: ='Source Data'!F26 -> 0.039868552 | F16: =F14/F2 -> 0.040466967
A18: Net Finance Costs | B18: ='Source Data'!C16 -> 600 | C18: ='Source Data'!D16 -> 677 | D18: ='Source Data'!E16 -> 740 | E18: ='Source Data'!F16 -> 811 | F18: =Assumptions!B9 -> 880
A20: PROFIT BEFORE TAX | B20: ='Source Data'!C17 -> 2091 | C20: ='Source Data'!D17 -> 2322 | D20: ='Source Data'!E17 -> 876 | E20: ='Source Data'!F17 -> 1374 | F20: =F13-Assumptions!B9 -> 2036.0444
A21: Income Tax Expense | B21: ='Source Data'!C18 -> 534 | C21: ='Source Data'!D18 -> 693 | D21: ='Source Data'!E18 -> 759 | E21: ='Source Data'!F18 -> 421 | F21: =F20*Assumptions!B10 -> 590.45288
A23: NET PROFIT AFTER TAX (Reported) | B23: ='Source Data'!C19 -> 1547 | C23: ='Source Data'!D19 -> 1618 | D23: ='Source Data'!E19 -> 108 | E23: ='Source Data'!F19 -> 963 | F23: =F20-F21 -> 1445.5915
A24: — Underlying NPAT | B24: ='Source Data'!C20 -> 1547 | C24: ='Source Data'!D20 -> 1618 | D24: ='Source Data'!E20 -> 1399 | E24: ='Source Data'!F20 -> 963 | F24: =F23 -> 1445.5915
A25: Net Margin % (Reported) | B25: ='Source Data'!C27 -> 0.02542359 | C25: ='Source Data'!D27 -> 0.025165645 | D25: ='Source Data'!E27 -> 0.0015900592 | E25: ='Source Data'!F27 -> 0.013940964 | F25: =F23/F2 -> 0.020060979
A27: YoY GROWTH
A28: Revenue Growth % | C28: =(C2-B2)/B2 -> 0.056615557 | D28: =(D2-C2)/C2 -> 0.056428283 | E28: =(E2-D2)/D2 -> 0.0170048 | F28: =(F2-E2)/E2 -> 0.043181815
A29: Gross Profit Growth % | C29: =(C5-B5)/B5 -> 0.075449252 | D29: =(D5-C5)/C5 -> 0.080111784 | E29: =(E5-D5)/D5 -> 0.014176369 | F29: =(F5-E5)/E5 -> 0.029415572
A30: Underlying EBIT Growth % | C30: =(C14-B14)/B14 -> 0.11445559 | D30: =(D14-C14)/C14 -> 0.10603535 | E30: =(E14-D14)/D14 -> -0.16973169 | F30: =(F14-E14)/E14 -> 0.058839655
A31: Underlying NPAT Growth % | C31: =(C24-B24)/B24 -> 0.045895281 | D31: =(D24-C24)/C24 -> -0.13535229 | E31: =(E24-D24)/D24 -> -0.31165118 | F31: =(F24-E24)/E24 -> 0.50113347

Sheet Balance Sheet
A1: Line Item | B1: FY2022 | C1: FY2023 | D1: FY2024 | E1: FY2025 | F1: FY2026E | G1: Notes
A2: ASSETS
A3: Total Current Assets | B3: ='Source Data'!C30 -> 6110 | C3: ='Source Data'!D30 -> 6375 | D3: ='Source Data'!E30 -> 6991 | E3: ='Source Data'!F30 -> 6991 | F3: =E3*(1+Assumptions!B12) -> 7305.595
A4: Total Non-Current Assets | B4: ='Source Data'!C31 -> 27163 | C4: ='Source Data'!D31 -> 27273 | D4: ='Source Data'!E31 -> 26945 | E4: ='Source Data'!F31 -> 26838 | F4: =E4*(1+Assumptions!B13) -> 26972.19
A5: TOTAL ASSETS | B5: =SUM(B3:B4) -> 33273 | C5: =SUM(C3:C4) -> 33648 | D5: =SUM(D3:D4) -> 33936 | E5: =SUM(E3:E4) -> 33829 | F5: =SUM(F3:F4) -> 34277.785 | G5: Current Assets + Non-Current Assets
A7: LIABILITIES
A8: Total Current Liabilities | B8: ='Source Data'!C33 -> 10750 | C8: ='Source Data'!D33 -> 11886 | D8: ='Source Data'!E33 -> 12819 | E8: ='Source Data'!F33 -> 12297 | F8: =E8*(1+Assumptions!B14) -> 12850.365
A9: Total Non-Current Liabilities | B9: ='Source Data'!C34 -> 16419 | C9: ='Source Data'!D34 -> 15197 | D9: ='Source Data'!E34 -> 15547 | E9: ='Source Data'!F34 -> 16570 | F9: =E9*(1+Assumptions!B15) -> 16619.71
A11: TOTAL LIABILITIES | B11: =SUM(B8:B9) -> 27169 | C11: =SUM(C8:C9) -> 27083 | D11: =SUM(D8:D9) -> 28366 | E11: =SUM(E8:E9) -> 28867 | F11: =SUM(F8:F9) -> 29470.075 | G11: Current Liabilities + Non-Current Liabilities
A13: EQUITY
A14: Total Equity | B14: ='Source Data'!C36 -> 6104 | C14: ='Source Data'!D36 -> 6565 | D14: ='Source Data'!E36 -> 5570 | E14: ='Source Data'!F36 -> 4962 | F14: =F5-F11 -> 4807.71
A16: TOTAL LIABILITIES + EQUITY | B16: =B11+B14 -> 33273 | C16: =C11+C14 -> 33648 | D16: =D11+D14 -> 33936 | E16: =E11+E14 -> 33829 | F16: =F11+F14 -> 34277.785 | G16: Must equal Total Assets
A17: Balance Check (TA – TL+E) | B17: =B5-B16 -> 0 | C17: =C5-C16 -> 0 | D17: =D5-D16 -> 0 | E17: =E5-E16 -> 0 | F17: =F5-F16 -> 0 | G17: Should be zero — confirms BS balances
A19: YoY GROWTH
A20: Total Assets Growth % | C20: =(C5-B5)/B5 -> 0.011270399 | D20: =(D5-C5)/C5 -> 0.0085592011 | E20: =(E5-D5)/D5 -> -0.0031529939 | F20: =(F5-E5)/E5 -> 0.01326628
A21: Total Liabilities Growth % | C21: =(C11-B11)/B11 -> -0.0031653723 | D21: =(D11-C11)/C11 -> 0.047372891 | E21: =(E11-D11)/D11 -> 0.01766199 | F21: =(F11-E11)/E11 -> 0.020891502
A22: Total Equity Growth % | C22: =(C14-B14)/B14 -> 0.075524246 | D22: =(D14-C14)/C14 -> -0.15156131 | E22: =(E14-D14)/D14 -> -0.10915619 | F22: =(F14-E14)/E14 -> -0.031094317
A24: COMPOSITION
A25: Equity / Total Assets % | B25: =B14/B5 -> 0.18345205 | C25: =C14/C5 -> 0.19510818 | D25: =D14/D5 -> 0.16413248 | E25: =E14/E5 -> 0.14667888 | F25: =F14/F5 -> 0.14025731
A26: Debt-to-Equity Ratio (TL/TE) | B26: =B11/B14 -> 4.4510157 | C26: =C11/C14 -> 4.1253618 | D26: =D11/D14 -> 5.0926391 | E26: =E11/E14 -> 5.8176139 | F26: =F11/F14 -> 6.129753
A27: Current Ratio (CA/CL) | B27: =B3/B8 -> 0.56837209 | C27: =C3/C8 -> 0.53634528 | D27: =D3/D8 -> 0.54536235 | E27: =E3/E8 -> 0.56851265 | F27: =F3/F8 -> 0.56851265

Sheet Cash Flow
A1: WOOLWORTHS GROUP (ASX: WOW) — CASH FLOW STATEMENT | AUD Millions
A2: FY2022–FY2025 sourced from Woolworths Annual Reports. FY2026E projected per Assumptions sheet.
A3: Line Item | B3: FY2022 | C3: FY2023 | D3: FY2024 | E3: FY2025 | F3: FY2026E
A4: OPERATING ACTIVITIES
A5: Operating Cash Flow | B5: 3378 | C5: 4754 | D5: 4359 | E5: 4550 | F5: 4228.26
A6: INVESTING ACTIVITIES
A7: Capital Expenditure | B7: -2457 | C7: -1844 | D7: -2277 | E7: -1926 | F7: -2100
A8: Investing Cash Flow | B8: -2457 | C8: -1844 | D8: -2277 | E8: -1926 | F8: -2100
A9: FREE CASH FLOW | B9: 921 | C9: 2910 | D9: 2082 | E9: 2624 | F9: 2128.26
A11: FINANCING ACTIVITIES
A12: Financing Cash Flow | B12: -1337 | C12: -2809 | D12: -1919 | E12: -2649 | F12: -2179
A14: NET CHANGE IN CASH | B14: -416 | C14: 101 | D14: 163 | E14: -25 | F14: -50.74
A16: YoY GROWTH
A17: OCF Growth % | C17: 0.40734162 | D17: -0.083087926 | E17: 0.043817389 | F17: -0.070712088
A18: FCF Growth % | C18: 2.1596091 | D18: -0.28453608 | E18: 0.26032661 | F18: -0.1889253
A19: FCF Conversion (FCF/OCF) | B19: 0.27264654 | C19: 0.61211611 | D19: 0.47763248 | E19: 0.5767033 | F19: 0.5033418

Sheet Variance Analysis
A1: WOOLWORTHS GROUP (ASX: WOW) — VARIANCE ANALYSIS | AUD Millions
A2: FY2024 vs FY2025 Actuals — variance highlights operational performance shift. Source: WOW Annual Reports.
A3: Line Item | B3: FY2024 ($m) | C3: FY2025 ($m) | D3: Variance ($m) | E3: Var %
A4: INCOME STATEMENT
A5: Revenue | B5: 67922 | C5: 69077 | D5: 1155 | E5: 0.0170048
A6: Cost of Sales | B6: 49370 | C6: 50262 | D6: 892 | E6: 0.018067652
A7: Gross Profit | B7: 18552 | C7: 18815 | D7: 263 | E7: 0.014176369
A8: Gross Margin % | B8: 0.273137 | C8: 0.272377 | D8: -0.00076 | E8: -0.0027824864
A10: OPERATING COSTS
A11: Branch Expenses | B11: 11707 | C11: 12768 | D11: 1061 | E11: 0.090629538
A12: Administration Expenses | B12: 5539 | C12: 4135 | D12: -1404 | E12: -0.25347536
A13: Total CODB (Reported) | B13: 17246 | C13: 16903 | D13: -343 | E13: -0.01988867
A14: One-off / Impairment Items | B14: 1701 | C14: 569 | D14: -1132 | E14: -0.66549089
A15: Underlying CODB | B15: 15545 | C15: 16334 | D15: 789 | E15: 0.05075587
A17: PROFITABILITY
A18: EBIT (Reported) | B18: 1616 | C18: 2185 | D18: 569 | E18: 0.35210396
A19: Underlying EBIT | B19: 3317 | C19: 2754 | D19: -563 | E19: -0.16973169
A20: Underlying EBIT Margin % | B20: 0.048835 | C20: 0.039869 | D20: -0.008966 | E20: -0.18359783
A21: Net Finance Costs | B21: 600 | C21: 811 | D21: 211 | E21: 0.35166667
A22: NPAT (Reported) | B22: 108 | C22: 963 | D22: 855 | E22: 7.9166667
A23: Underlying NPAT | B23: 1399 | C23: 963 | D23: -436 | E23: -0.31165118
A25: CASH FLOW
A26: Operating Cash Flow | B26: 4359 | C26: 4550 | D26: 191 | E26: 0.043817389
A27: Free Cash Flow | B27: 2082 | C27: 2624 | D27: 542 | E27: 0.26032661

Sheet Dashboard
A1: WOOLWORTHS GROUP (ASX: WOW) — FINANCIAL DASHBOARD | AUD Millions
A2: Summary view | FY2022–FY2026E | Prepared by Ayush Bhatt | Sources: WOW Annual Reports FY2022–FY2025
A3: Metric | B3: FY2022 | C3: FY2023 | D3: FY2024 | E3: FY2025 | F3: FY2026E
A4: REVENUE & PROFITABILITY
A5: Revenue ($m) | B5: 60849 | C5: 64294 | D5: 67922 | E5: 69077 | F5: 72059.87
A6: Revenue Growth % | C6: 0.0566 | D6: 0.0564 | E6: 0.017 | F6: 0.0432
A7: Gross Profit ($m) | B7: 15971 | C7: 17176 | D7: 18552 | E7: 18815 | F7: 19368.45
A8: Gross Margin % | B8: 0.2625 | C8: 0.2671 | D8: 0.2731 | E8: 0.2724 | F8: 0.2688
A10: EBIT & EARNINGS
A11: Underlying EBIT ($m) | B11: 2691 | C11: 2999 | D11: 3317 | E11: 2754 | F11: 2916.04
A12: Underlying EBIT Margin % | B12: 0.0442 | C12: 0.0466 | D12: 0.0488 | E12: 0.0399 | F12: 0.0405
A13: NPAT Reported ($m) | B13: 1547 | C13: 1618 | D13: 108 | E13: 963 | F13: 1445.59
A14: Underlying NPAT ($m) | B14: 1547 | C14: 1618 | D14: 1399 | E14: 963 | F14: 1445.59
A16: CASH FLOW
A17: Operating Cash Flow ($m) | B17: 3378 | C17: 4754 | D17: 4359 | E17: 4550 | F17: 4228.26
A18: Free Cash Flow ($m) | B18: 921 | C18: 2910 | D18: 2082 | E18: 2624 | F18: 2128.26
A19: FCF Conversion (FCF/OCF) | B19: 0.2727 | C19: 0.6121 | D19: 0.4778 | E19: 0.5767 | F19: 0.5033418
A21: BALANCE SHEET
A22: Total Assets ($m) | B22: 33273 | C22: 33648 | D22: 33936 | E22: 33829 | F22: 34277.79
A23: Total Equity ($m) | B23: 6104 | C23: 6565 | D23: 5570 | E23: 4962 | F23: 4807.71
A24: Debt-to-Equity (TL/TE) | B24: 4.451 | C24: 4.125 | D24: 5.093 | E24: 5.818 | F24: 6.13
A25: Current Ratio (CA/CL) | B25: 0.568 | C25: 0.536 | D25: 0.545 | E25: 0.569 | F25: 0.569
A28: FY2026E SCENARIO SUMMARY
A29: Metric | B29: Low Case | C29: Base Case | D29: High Case | E29: Basis
A30: Revenue Growth % | B30: 2.82% | C30: 4.32% | D30: 5.82% | E30: 3-yr CAGR range
A31: Gross Margin % | B31: 26.5% | C31: 26.9% | D31: 27.2% | E31: Avg FY2022–FY2025
A32: Underlying CODB % | B32: 22.4% | C32: 22.8% | D32: 23.3% | E32: Avg FY2022–FY2025
A33: Net Finance Costs | B33: $870m | C33: $880m | D33: $890m | E33: FY2025 + avg movement
A34: Effective Tax Rate | B34: 28.0% | C34: 29.0% | D34: 30.0% | E34: Normalised post FY2024

Sheet PBI_Data
A1: Year | B1: Metric | C1: Category | D1: Sub_Category | E1: Value | F1: Unit | G1: Value_Type | H1: Is_Forecast | I1: Display_Label
A2: FY2022 | B2: Revenue | C2: P&L | D2: Income Statement | E2: 60849 | F2: $m | G2: Dollar | H2: No | I2: $60,849m
A3: FY2023 | B3: Revenue | C3: P&L | D3: Income Statement | E3: 64294 | F3: $m | G3: Dollar | H3: No | I3: $64,294m
A4: FY2024 | B4: Revenue | C4: P&L | D4: Income Statement | E4: 67922 | F4: $m | G4: Dollar | H4: No | I4: $67,922m
A5: FY2025 | B5: Revenue | C5: P&L | D5: Income Statement | E5: 69077 | F5: $m | G5: Dollar | H5: No | I5: $69,077m
A6: FY2026E | B6: Revenue | C6: P&L | D6: Income Statement | E6: 72059.87 | F6: $m | G6: Dollar | H6: Yes | I6: $72,060m
A7: FY2022 | B7: Cost of Sales | C7: P&L | D7: Income Statement | E7: 44878 | F7: $m | G7: Dollar | H7: No | I7: $44,878m
A8: FY2023 | B8: Cost of Sales | C8: P&L | D8: Income Statement | E8: 47118 | F8: $m | G8: Dollar | H8: No | I8: $47,118m
A9: FY2024 | B9: Cost of Sales | C9: P&L | D9: Income Statement | E9: 49370 | F9: $m | G9: Dollar | H9: No | I9: $49,370m
A10: FY2025 | B10: Cost of Sales | C10: P&L | D10: Income Statement | E10: 50262 | F10: $m | G10: Dollar | H10: No | I10: $50,262m
A11: FY2026E | B11: Cost of Sales | C11: P&L | D11: Income Statement | E11: 52691.42 | F11: $m | G11: Dollar | H11: Yes | I11: $52,691m
A12: FY2022 | B12: Gross Profit | C12: P&L | D12: Income Statement | E12: 15971 | F12: $m | G12: Dollar | H12: No | I12: $15,971m
A13: FY2023 | B13: Gross Profit | C13: P&L | D13: Income Statement | E13: 17176 | F13: $m | G13: Dollar | H13: No | I13: $17,176m
... A202: FY2025 | B202: Revenue | C202: Variance | D202: P&L | E202: 69077 | F202: $m | G202: Dollar | H202: No | I202: $69,077m
A203: Variance $m | B203: Revenue | C203: Variance | D203: P&L | E203: 1155 | F203: $m | G203: Variance_Dollar | H203: No
A204: Variance % | B204: Revenue | C204: Variance | D204: P&L | E204: 1.7005 | F204: % | G204: Variance_Pct | H204: No | I204: 1.7%
A205: FY2024 | B205: Cost of Sales | C205: Variance | D205: P&L | E205: 49370 | F205: $m | G205: Dollar | H205: No | I205: $49,370m
A206: FY2025 | B206: Cost of Sales | C206: Variance | D206: P&L | E206: 50262 | F206: $m | G206: Dollar | H206: No | I206: $50,262m
A207: Variance $m | B207: Cost of Sales | C207: Variance | D207: P&L | E207: 892 | F207: $m | G207: Variance_Dollar | H207: No
A208: Variance % | B208: Cost of Sales | C208: Variance | D208: P&L | E208: 1.8068 | F208: % | G208: Variance_Pct | H208: No | I208: 1.8%
A209: FY2024 | B209: Gross Profit | C209: Variance | D209: P&L | E209: 18552 | F209: $m | G209: Dollar | H209: No | I209: $18,552m
A210: FY2025 | B210: Gross Profit | C210: Variance | D210: P&L | E210: 18815 | F210: $m | G210: Dollar | H210: No | I210: $18,815m
A211: Variance $m | B211: Gross Profit | C211: Variance | D211: P&L | E211: 263 | F211: $m | G211: Variance_Dollar | H211: No
A212: Variance % | B212: Gross Profit | C212: Variance | D212: P&L | E212: 1.4176 | F212: % | G212: Variance_Pct | H212: No | I212: 1.4%
A213: FY2024 | B213: Branch Expenses | C213: Variance | D213: P&L | E213: 11707 | F213: $m | G213: Dollar | H213: No | I213: $11,707m
A214: FY2025 | B214: Branch Expenses | C214: Variance | D214: P&L | E214: 12768 | F214: $m | G214: Dollar | H214: No | I214: $12,768m
A215: Variance $m | B215: Branch Expenses | C215: Variance | D215: P&L | E215: 1061 | F215: $m | G215: Variance_Dollar | H215: No
A216: Variance % | B216: Branch Expenses | C216: Variance | D216: P&L | E216: 9.063 | F216: % | G216: Variance_Pct | H216: No | I216: 9.1%
A217: FY2024 | B217: Admin Expenses | C217: Variance | D217: P&L | E217: 5539 | F217: $m | G217: Dollar | H217: No | I217: $5,539m
A218: FY2025 | B218: Admin Expenses | C218: Variance | D218: P&L | E218: 4135 | F218: $m | G218: Dollar | H218: No | I218: $4,135m
A219: Variance $m | B219: Admin Expenses | C219: Variance | D219: P&L | E219: -1404 | F219: $m | G219: Variance_Dollar | H219: No
A220: Variance % | B220: Admin Expenses | C220: Variance | D220: P&L | E220: -25.3475 | F220: % | G220: Variance_Pct | H220: No | I220: -25.3%
A221: FY2024 | B221: Total CODB Reported | C221: Variance | D221: P&L | E221: 17246 | F221: $m | G221: Dollar | H221: No | I221: $17,246m
A222: FY2025 | B222: Total CODB Reported | C222: Variance | D222: P&L | E222: 16903 | F222: $m | G222: Dollar | H222: No | I222: $16,903m
A223: Variance $m | B223: Total CODB Reported | C223: Variance | D223: P&L | E223: -343 | F223: $m | G223: Variance_Dollar | H223: No
A224: Variance % | B224: Total CODB Reported | C224: Variance | D224: P&L | E224: -1.9889 | F224: % | G224: Variance_Pct | H224: No | I224: -2.0%
A225: FY2024 | B225: Underlying CODB | C225: Variance | D225: P&L | E225: 15545 | F225: $m | G225: Dollar | H225: No | I225: $15,545m
A226: FY2025 | B226: Underlying CODB | C226: Variance | D226: P&L | E226: 16334 | F226: $m | G226: Dollar | H226: No | I226: $16,334m
A227: Variance $m | B227: Underlying CODB | C227: Variance | D227: P&L | E227: 789 | F227: $m | G227: Variance_Dollar | H227: No
A228: Variance % | B228: Underlying CODB | C228: Variance | D228: P&L | E228: 5.0756 | F228: % | G228: Variance_Pct | H228: No | I228: 5.1%
...

Sheet Waterfall
A1: Scenario | B1: Metric | C1: Value | D1: Metric_Sort | E1: Scenario_Sort
A2: Low Case | B2: Revenue | C2: 71026 | D2: 1 | E2: 1
A3: Low Case | B3: COGS | C3: 52169 | D3: 2 | E3: 1
A4: Low Case | B4: Gross Profit | C4: 18857 | D4: 3 | E4: 1
A5: Low Case | B5: Underlying CODB | C5: 15911 | D5: 4 | E5: 1
A6: Low Case | B6: Underlying EBIT | C6: 2946 | D6: 5 | E6: 1
A7: Low Case | B7: Net Finance Costs | C7: 870 | D7: 6 | E7: 1
A8: Low Case | B8: Underlying NPAT | C8: 1493 | D8: 7 | E8: 1
A9: Base Case | B9: Revenue | C9: 72060 | D9: 1 | E9: 2
A10: Base Case | B10: COGS | C10: 52690 | D10: 2 | E10: 2
A11: Base Case | B11: Gross Profit | C11: 19370 | D11: 3 | E11: 2
A12: Base Case | B12: Underlying CODB | C12: 16452 | D12: 4 | E12: 2
A13: Base Case | B13: Underlying EBIT | C13: 2918 | D13: 5 | E13: 2
... A22: High Case | B22: Underlying NPAT | C22: 1411 | D22: 7 | E22: 3
